Workbook

Sheet Sales
A1: DATE | B1: STAFF NAME | C1: SERVICE | D1: CHARGES | E1: COMMISSION RATE | F1: STAFF SHARES | G1: COMPANY SHARES
A2: 46174 | B2: TREVOR | C2: FACIAL | D2: 3500 | E2: 0.3 | F2: =(D2*E2) -> 1050 | G2: =(D2-F2) -> 2450
A3: 46174 | B3: CHRIS | C3: MASSAGE | D3: 4000 | E3: 0.4 | F3: =(D3*E3) -> 1600 | G3: =(D3-F3) -> 2400
A4: 46174 | B4: AUSTIN | C4: HAIR CUT | D4: 2000 | E4: 0.45 | F4: =(D4*E4) -> 900 | G4: =(D4-F4) -> 1100
A5: 46174 | B5: MARTIN | C5: MANICURE | D5: 2500 | E5: 0.5 | F5: =(D5*E5) -> 1250 | G5: =(D5-F5) -> 1250
A6: 46174 | B6: BEN | C6: PEDICURE | D6: 2500 | E6: 0.65 | F6: =(D6*E6) -> 1625 | G6: =(D6-F6) -> 875
A7: TOTAL - 01/06/2026 | D7: =SUM(D2:D6) -> 14500 | F7: =SUM(F2:F6) -> 6425 | G7: =SUM(G2:G6) -> 8075
A9: DATE | B9: STAFF NAME | C9: SERVICE | D9: CHARGES | E9: COMMISSION RATE | F9: STAFF SHARES | G9: COMPANY SHARES
A10: 46175 | B10: TREVOR | C10: FACIAL | D10: 4599 | E10: 0.3 | F10: =(D10*E10) -> 1379.7 | G10: =(D10-F10) -> 3219.3
A11: 46175 | B11: CHRIS | C11: MASSAGE | D11: 9988 | E11: 0.4 | F11: =(D11*E11) -> 3995.2 | G11: =(D11-F11) -> 5992.8
A12: 46175 | B12: AUSTIN | C12: HAIR CUT | D12: 3200 | E12: 0.45 | F12: =(D12*E12) -> 1440 | G12: =(D12-F12) -> 1760
A13: 46175 | B13: MARTIN | C13: MANICURE | D13: 7654 | E13: 0.5 | F13: =(D13*E13) -> 3827 | G13: =(D13-F13) -> 3827
A14: 46175 | B14: BEN | C14: PEDICURE | D14: 9876 | E14: 0.65 | F14: =(D14*E14) -> 6419.4 | G14: =(D14-F14) -> 3456.6
A15: TOTAL - 02/06/2026 | D15: =SUM(D10:D14) -> 35317 | F15: =SUM(F10:F14) -> 17061.3 | G15: =SUM(G10:G14) -> 18255.7
A17: DATE | B17: STAFF NAME | C17: SERVICE | D17: CHARGES | E17: COMMISSION RATE | F17: STAFF SHARES | G17: COMPANY SHARES
A18: 46176 | B18: TREVOR | C18: FACIAL | D18: 5443 | E18: 0.3 | F18: =(D18*E18) -> 1632.9 | G18: =(D18-F18) -> 3810.1
A19: 46176 | B19: CHRIS | C19: MASSAGE | D19: 8788 | E19: 0.4 | F19: =(D19*E19) -> 3515.2 | G19: =(D19-F19) -> 5272.8
A20: 46176 | B20: AUSTIN | C20: HAIR CUT | D20: 9800 | E20: 0.45 | F20: =(D20*E20) -> 4410 | G20: =(D20-F20) -> 5390
A21: 46176 | B21: MARTIN | C21: MANICURE | D21: 8765 | E21: 0.5 | F21: =(D21*E21) -> 4382.5 | G21: =(D21-F21) -> 4382.5
A22: 46176 | B22: BEN | C22: PEDICURE | D22: 5432 | E22: 0.65 | F22: =(D22*E22) -> 3530.8 | G22: =(D22-F22) -> 1901.2
A23: TOTAL - 03/06/2026 | D23: =SUM(D18:D22) -> 38228 | F23: =SUM(F18:F22) -> 17471.4 | G23: =SUM(G18:G22) -> 20756.6
A25: DATE | B25: STAFF NAME | C25: SERVICE | D25: CHARGES | E25: COMMISSION RATE | F25: STAFF SHARES | G25: COMPANY SHARES
A26: 46177 | B26: TREVOR | C26: FACIAL | D26: 4321 | E26: 0.3 | F26: =(D26*E26) -> 1296.3 | G26: =(D26-F26) -> 3024.7
A27: 46177 | B27: CHRIS | C27: MASSAGE | D27: 6543 | E27: 0.4 | F27: =(D27*E27) -> 2617.2 | G27: =(D27-F27) -> 3925.8
A28: 46177 | B28: AUSTIN | C28: HAIR CUT | D28: 9876 | E28: 0.45 | F28: =(D28*E28) -> 4444.2 | G28: =(D28-F28) -> 5431.8
A29: 46177 | B29: MARTIN | C29: MANICURE | D29: 4321 | E29: 0.5 | F29: =(D29*E29) -> 2160.5 | G29: =(D29-F29) -> 2160.5
A30: 46177 | B30: BEN | C30: PEDICURE | D30: 7658 | E30: 0.65 | F30: =(D30*E30) -> 4977.7 | G30: =(D30-F30) -> 2680.3
A31: TOTAL - 04/06/2026 | D31: =SUM(D26:D30) -> 32719 | F31: =SUM(F26:F30) -> 15495.9 | G31: =SUM(G26:G30) -> 17223.1
A33: DATE | B33: STAFF NAME | C33: SERVICE | D33: CHARGES | E33: COMMISSION RATE | F33: STAFF SHARES | G33: COMPANY SHARES
A34: 46178 | B34: TREVOR | C34: FACIAL | D34: 4321 | E34: 0.3 | F34: =(D34*E34) -> 1296.3 | G34: =(D34-F34) -> 3024.7
A35: 46178 | B35: CHRIS | C35: MASSAGE | D35: 3421 | E35: 0.4 | F35: =(D35*E35) -> 1368.4 | G35: =(D35-F35) -> 2052.6
A36: 46178 | B36: AUSTIN | C36: HAIR CUT | D36: 5654 | E36: 0.45 | F36: =(D36*E36) -> 2544.3 | G36: =(D36-F36) -> 3109.7
A37: 46178 | B37: MARTIN | C37: MANICURE | D37: 5432 | E37: 0.5 | F37: =(D37*E37) -> 2716 | G37: =(D37-F37) -> 2716
A38: 46178 | B38: BEN | C38: PEDICURE | D38: 9876 | E38: 0.65 | F38: =(D38*E38) -> 6419.4 | G38: =(D38-F38) -> 3456.6
A39: TOTAL - 05/06/2026 | D39: =SUM(D34:D38) -> 28704 | F39: =SUM(F34:F38) -> 14344.4 | G39: =SUM(G34:G38) -> 14359.6
A41: DATE | B41: STAFF NAME | C41: SERVICE | D41: CHARGES | E41: COMMISSION RATE | F41: STAFF SHARES | G41: COMPANY SHARES
A42: 46179 | B42: TREVOR | C42: FACIAL | D42: 2100 | E42: 0.3 | F42: =(D42*E42) -> 630 | G42: =(D42-F42) -> 1470
A43: 46179 | B43: CHRIS | C43: MASSAGE | D43: 2200 | E43: 0.4 | F43: =(D43*E43) -> 880 | G43: =(D43-F43) -> 1320
A44: 46179 | B44: AUSTIN | C44: HAIR CUT | D44: 2300 | E44: 0.45 | F44: =(D44*E44) -> 1035 | G44: =(D44-F44) -> 1265
A45: 46179 | B45: MARTIN | C45: MANICURE | D45: 2400 | E45: 0.5 | F45: =(D45*E45) -> 1200 | G45: =(D45-F45) -> 1200
...

Sheet Report
A1: Staff Name | B1: Total Sales | C1: Gross Commission | D1: Company Share
A2: TREVOR | B2: =SUMIF(Sales!$B:$B,A2,Sales!$D:$D) -> 24284 | C2: =SUMIF(Sales!$B:$B,A2,Sales!$F:$F) -> 7285.2 | D2: =SUMIF(Sales!$B:$B,A2,Sales!$G:$G) -> 16998.8
A3: CHRIS | B3: =SUMIF(Sales!$B:$B,A3,Sales!$D:$D) -> 34940 | C3: =SUMIF(Sales!$B:$B,A3,Sales!$F:$F) -> 13976 | D3: =SUMIF(Sales!$B:$B,A3,Sales!$G:$G) -> 20964
A4: AUSTIN | B4: =SUMIF(Sales!$B:$B,A4,Sales!$D:$D) -> 32830 | C4: =SUMIF(Sales!$B:$B,A4,Sales!$F:$F) -> 14773.5 | D4: =SUMIF(Sales!$B:$B,A4,Sales!$G:$G) -> 18056.5
A5: MARTIN | B5: =SUMIF(Sales!$B:$B,A5,Sales!$D:$D) -> 31072 | C5: =SUMIF(Sales!$B:$B,A5,Sales!$F:$F) -> 15536 | D5: =SUMIF(Sales!$B:$B,A5,Sales!$G:$G) -> 15536
A6: BEN | B6: =SUMIF(Sales!$B:$B,A6,Sales!$D:$D) -> 37897 | C6: =SUMIF(Sales!$B:$B,A6,Sales!$F:$F) -> 24633.05 | D6: =SUMIF(Sales!$B:$B,A6,Sales!$G:$G) -> 13263.95
